Workbook

Sheet 📋 INDEX & TIPS
A1: 🐱 Meo's Vietnamese B2 Word List — COMPLETE SERIES (All 5 Parts)
A2: =CONCATENATE("Southern Vietnamese (Saigon) | For Cantonese Speakers | ",TEXT(B10,"#,##0")," words — Series Complete 🎯") -> Southern Vietnamese (Saigon) | For Cantonese Speakers | 156 words — Series Complete 🎯
A4: SERIES OVERVIEW
A5: Part | B5: Words | D5: Coverage
A6: Part 1 — Foundations | B6: =COUNTIF('📚 All Words (Combined)'!$B:$B,"Part 1 — Foundations") -> 659 | D6: Pronouns, Numbers, Time, Core Verbs, Adjectives, Food, Places, Body & more
A7: Part 2 — Intermediate | B7: =COUNTIF('📚 All Words (Combined)'!$B:$B,"Part 2 — Intermediate") -> 524 | D7: Business, Legal, Tech, Health, Culture, Abstract Concepts, Grammar & Particles
A8: Part 3 — Advanced | B8: =COUNTIF('📚 All Words (Combined)'!$B:$B,"Part 3 — Advanced") -> 339 | D8: Idioms, Formal Writing, Spoken Southern, Economics, Arts, Discourse Markers
A9: Part 4 — Completion | B9: =COUNTIF('📚 All Words (Combined)'!$B:$B,"Part 4 — Completion") -> 284 | D9: Personality, Cause/Effect, Academic, Emotions, Animals, High Frequency Fill
A10: Part 5 — Final | B10: =COUNTIF('📚 All Words (Combined)'!$B:$B,"Part 5 — Final") -> 156 | D10: Work, Shopping, Apps, Tones, Grammar Structures, Essential Fill
A11: 🏆 GRAND TOTAL — Complete Series | B11: =SUM(B6,B7,B8,B9,B10) -> 1962 | D11: 🎯 Series complete! Target: 2,000 words for B2 by June 2026
A14: 📅 STUDY PACE GUIDE — B2 BY JUNE 2026
A15: Period | C15: Focus | D15: Method
A16: Feb–Mar 2026 | C16: Part 1 (659 words) | D16: ~15 words/day — Foundation sprint
A17: Mar–Apr 2026 | C17: Part 2 (524 words) | D17: ~12 words/day — Build intermediate vocab
A18: Apr–May 2026 | C18: Parts 3+4 (623 words) | D18: ~10 words/day — Advanced push
A19: May–Jun 2026 | C19: Part 5 + Review | D19: Anki SRS + shadowing + conversation practice
A20: Jun 2026 | C20: B2 Test | D20: You've got this! Sino-Viet advantage is huge 💪
A23: PART 1 — FOUNDATIONS
A24: Southern Vietnamese (Saigon) | Cantonese tones | Sino-Vietnamese connections highlighted
A25: Category | B25: Words | D25: Key Learning Tip
A26: Pronouns & People | B26: =COUNTIFS('📚 All Words (Combined)'!$B:$B,"Part 1 — Foundations",'📚 All Words (Combined)'!$G:$G,"Pronouns & People") -> 27 | D26: Master pronouns first — they reflect social relationships and change constantly
A27: Numbers | B27: =COUNTIFS('📚 All Words (Combined)'!$B:$B,"Part 1 — Foundations",'📚 All Words (Combined)'!$G:$G,"Numbers") -> 20 | D27: Sino-Viet numbers map closely to Cantonese: mot=jat, hai=ji, ba=saam...
A28: Time | B28: =COUNTIFS('📚 All Words (Combined)'!$B:$B,"Part 1 — Foundations",'📚 All Words (Combined)'!$G:$G,"Time") -> 36 | D28: No verb conjugation! Use da(past)/dang(now)/se(future) particles instead
A29: Greetings | B29: =COUNTIFS('📚 All Words (Combined)'!$B:$B,"Part 1 — Foundations",'📚 All Words (Combined)'!$G:$G,"Greetings") -> 14 | D29: Essential daily phrases — 'da' is Southern polite 'yes', not Northern 'vang'
A30: Core Verbs | B30: =COUNTIFS('📚 All Words (Combined)'!$B:$B,"Part 1 — Foundations",'📚 All Words (Combined)'!$G:$G,"Core Verbs") -> 76 | D30: Backbone vocabulary — learn these 80 verbs before anything else
A31: Adjectives | B31: =COUNTIFS('📚 All Words (Combined)'!$B:$B,"Part 1 — Foundations",'📚 All Words (Combined)'!$G:$G,"Adjectives") -> 57 | D31: Adjectives come AFTER the noun (opposite of English but like some Chinese patterns)
A32: Question Words | B32: =COUNTIFS('📚 All Words (Combined)'!$B:$B,"Part 1 — Foundations",'📚 All Words (Combined)'!$G:$G,"Question Words") -> 11 | D32: Learn these 11 words and you can ask almost any question
A33: Prepositions | B33: =COUNTIFS('📚 All Words (Combined)'!$B:$B,"Part 1 — Foundations",'📚 All Words (Combined)'!$G:$G,"Prepositions") -> 16 | D33: Spatial and relational words — critical for giving/following directions
A34: Connectors | B34: =COUNTIFS('📚 All Words (Combined)'!$B:$B,"Part 1 — Foundations",'📚 All Words (Combined)'!$G:$G,"Connectors") -> 15 | D34: Build complex sentences — ~80% of these are Sino-Vietnamese!
A35: Food & Drink | B35: =COUNTIFS('📚 All Words (Combined)'!$B:$B,"Part 1 — Foundations",'📚 All Words (Combined)'!$G:$G,"Food & Drink") -> 37 | D35: Crucial for daily survival — huge regional variation (heo vs lon, ly vs coc)
A36: Transport | B36: =COUNTIFS('📚 All Words (Combined)'!$B:$B,"Part 1 — Foundations",'📚 All Words (Combined)'!$G:$G,"Transport") -> 23 | D36: Essential for HCMC — xe may (motorbike) culture is everywhere
A37: Places | B37: =COUNTIFS('📚 All Words (Combined)'!$B:$B,"Part 1 — Foundations",'📚 All Words (Combined)'!$G:$G,"Places") -> 36 | D37: Combines with verbs of movement — di/den/ve create powerful phrases
A38: Body & Health | B38: =COUNTIFS('📚 All Words (Combined)'!$B:$B,"Part 1 — Foundations",'📚 All Words (Combined)'!$G:$G,"Body & Health") -> 29 | D38: Most medical terms are Sino-Viet — huge advantage for you!
A39: Shopping & Money | B39: =COUNTIFS('📚 All Words (Combined)'!$B:$B,"Part 1 — Foundations",'📚 All Words (Combined)'!$G:$G,"Shopping & Money") -> 20 | D39: Bargaining is cultural — master price words immediately
A40: Work & Education | B40: =COUNTIFS('📚 All Words (Combined)'!$B:$B,"Part 1 — Foundations",'📚 All Words (Combined)'!$G:$G,"Work & Education") -> 25 | D40: Nearly all professional terms are Sino-Vietnamese
A41: Technology | B41: =COUNTIFS('📚 All Words (Combined)'!$B:$B,"Part 1 — Foundations",'📚 All Words (Combined)'!$G:$G,"Technology") -> 17 | D41: Mix of Sino-Viet and loanwords from English/French
A42: Nature | B42: =COUNTIFS('📚 All Words (Combined)'!$B:$B,"Part 1 — Foundations",'📚 All Words (Combined)'!$G:$G,"Nature") -> 25 | D42: Weather vocab important — tropical climate means rain/heat talk is constant
A43: Feelings | B43: =COUNTIFS('📚 All Words (Combined)'!$B:$B,"Part 1 — Foundations",'📚 All Words (Combined)'!$G:$G,"Feelings") -> 13 | D43: Emotional vocabulary for deeper, more natural conversation
A44: Social & Cultural | B44: =COUNTIFS('📚 All Words (Combined)'!$B:$B,"Part 1 — Foundations",'📚 All Words (Combined)'!$G:$G,"Social & Cultural") -> 20 | D44: Essential for cultural understanding and context
A45: Adverbs | B45: =COUNTIFS('📚 All Words (Combined)'!$B:$B,"Part 1 — Foundations",'📚 All Words (Combined)'!$G:$G,"Adverbs") -> 24 | D45: Rat (very) and qua (too much) are used constantly — learn these early!
...

Sheet 📚 All Words (Combined)
A1: # | B1: Part | C1: Vietnamese (Southern) | D1: English Meaning | E1: Chinese Characters | F1: Cantonese Pronunciation | G1: Category | H1: Notes / Sino-Viet Connection
A2: 1 | B2: Part 1 — Foundations | C2: tôi | D2: I / me | E2: 我 | F2: ngoh | G2: Pronouns & People
A3: 2 | B3: Part 1 — Foundations | C3: bạn | D3: you (friend/peer) | E3: 你 | F3: nei | G3: Pronouns & People
A4: 3 | B4: Part 1 — Foundations | C4: anh | D4: he / older brother / you (to older male) | E4: 兄 | F4: hing | G4: Pronouns & People
A5: 4 | B5: Part 1 — Foundations | C5: chị | D5: she / older sister / you (to older female) | E5: 姐 | F5: ze | G5: Pronouns & People
A6: 5 | B6: Part 1 — Foundations | C6: em | D6: younger sibling / I (to elder) | E6: 弟/妹 | F6: dai/mui | G6: Pronouns & People
A7: 6 | B7: Part 1 — Foundations | C7: họ | D7: they / them | E7: 他們 | F7: keoi-dei | G7: Pronouns & People
A8: 7 | B8: Part 1 — Foundations | C8: chúng tôi | D8: we (excl. listener) | E8: 我們 | F8: ngo-dei | G8: Pronouns & People
A9: 8 | B9: Part 1 — Foundations | C9: chúng ta | D9: we (incl. listener) | E9: 咱們 | F9: zaan-dei | G9: Pronouns & People
A10: 9 | B10: Part 1 — Foundations | C10: ông | D10: grandfather / Mr. / you (elderly man) | E10: 老爺/先生 | F10: lo-ye/sin-saang | G10: Pronouns & People
A11: 10 | B11: Part 1 — Foundations | C11: bà | D11: grandmother / Mrs. / you (elderly woman) | E11: 婆婆/太太 | F11: po-po/taai-taai | G11: Pronouns & People
A12: 11 | B12: Part 1 — Foundations | C12: cô | D12: aunt / Miss / you (young woman) | E12: 姑 | F12: gu | G12: Pronouns & People
A13: 12 | B13: Part 1 — Foundations | C13: chú | D13: uncle / you (middle-aged man) | E13: 叔 | F13: suk | G13: Pronouns & People
A14: 13 | B14: Part 1 — Foundations | C14: người | D14: person / people | E14: 人 | F14: jan | G14: Pronouns & People | H14: Sino-Viet: nhân
A15: 14 | B15: Part 1 — Foundations | C15: con | D15: child / classifier for animals | E15: 子 | F15: zi | G15: Pronouns & People
A16: 15 | B16: Part 1 — Foundations | C16: cha / bố | D16: father | E16: 父 | F16: fu | G16: Pronouns & People
A17: 16 | B17: Part 1 — Foundations | C17: mẹ / má | D17: mother | E17: 母 | F17: mou | G17: Pronouns & People | H17: má is Southern
A18: 17 | B18: Part 1 — Foundations | C18: con trai | D18: son / boy | E18: 兒子 | F18: ji-zi | G18: Pronouns & People
A19: 18 | B19: Part 1 — Foundations | C19: con gái | D19: daughter / girl | E19: 女兒 | F19: neoi-ji | G19: Pronouns & People
A20: 19 | B20: Part 1 — Foundations | C20: anh trai | D20: older brother | E20: 兄 | F20: hing | G20: Pronouns & People
A21: 20 | B21: Part 1 — Foundations | C21: chị gái | D21: older sister | E21: 姐姐 | F21: ze-ze | G21: Pronouns & People
A22: 21 | B22: Part 1 — Foundations | C22: em trai | D22: younger brother | E22: 弟弟 | F22: dai-dai | G22: Pronouns & People
A23: 22 | B23: Part 1 — Foundations | C23: em gái | D23: younger sister | E23: 妹妹 | F23: mui-mui | G23: Pronouns & People
A24: 23 | B24: Part 1 — Foundations | C24: bạn bè | D24: friends | E24: 朋友 | F24: pang-jau | G24: Pronouns & People
A25: 24 | B25: Part 1 — Foundations | C25: gia đình | D25: family | E25: 家庭 | F25: gaa-ting | G25: Pronouns & People | H25: Sino-Viet: gia đình
A26: 25 | B26: Part 1 — Foundations | C26: vợ | D26: wife | E26: 妻 | F26: chai | G26: Pronouns & People
A27: 26 | B27: Part 1 — Foundations | C27: chồng | D27: husband | E27: 夫 | F27: fu | G27: Pronouns & People
A28: 27 | B28: Part 1 — Foundations | C28: cháu | D28: niece/nephew/grandchild | E28: 侄/孫 | F28: zat/syun | G28: Pronouns & People
A29: 28 | B29: Part 1 — Foundations | C29: không | D29: zero | E29: 零 | F29: ling | G29: Numbers
A30: 29 | B30: Part 1 — Foundations | C30: một | D30: one | E30: 一 | F30: jat | G30: Numbers
A31: 30 | B31: Part 1 — Foundations | C31: hai | D31: two | E31: 二 | F31: ji | G31: Numbers
A32: 31 | B32: Part 1 — Foundations | C32: ba | D32: three | E32: 三 | F32: saam | G32: Numbers
A33: 32 | B33: Part 1 — Foundations | C33: bốn | D33: four | E33: 四 | F33: sei | G33: Numbers
A34: 33 | B34: Part 1 — Foundations | C34: năm | D34: five / year | E34: 五/年 | F34: ng/nin | G34: Numbers | H34: same word means year too
A35: 34 | B35: Part 1 — Foundations | C35: sáu | D35: six | E35: 六 | F35: luk | G35: Numbers
A36: 35 | B36: Part 1 — Foundations | C36: bảy | D36: seven | E36: 七 | F36: cat | G36: Numbers
A37: 36 | B37: Part 1 — Foundations | C37: tám | D37: eight | E37: 八 | F37: baat | G37: Numbers
A38: 37 | B38: Part 1 — Foundations | C38: chín | D38: nine | E38: 九 | F38: gau | G38: Numbers
A39: 38 | B39: Part 1 — Foundations | C39: mười | D39: ten | E39: 十 | F39: sap | G39: Numbers
A40: 39 | B40: Part 1 — Foundations | C40: mười một | D40: eleven | E40: 十一 | F40: sap-jat | G40: Numbers
...
